Workbook

Sheet Final_table
B1: Rock | C1: Crystallization age | D1: Metamorphic age | E1: Hudsonian metamorphism | F1: Inherited age | G1: Area | H1: Reference | I1: Order
B2: U vein | D2: 1774 ±9 (Urn) | G2: Hook Lake | H2: Mercadier et al., 2013 | I2: {=VALUE(_xlfn.XLOOKUP(TRUE, ISNUMBER(SEARCH('Order table'!$B$3:$B$11,Final_table!B34)), 'Order table'!$C$3:$C$11))} -> 8 | J2: 1
B3: U vein | C3: 1805 ±11 (Urn) | G3: Hook Lake | H3: Mercadier et al., 2013 | I3: {=VALUE(_xlfn.XLOOKUP(TRUE, ISNUMBER(SEARCH('Order table'!$B$3:$B$11,Final_table!B35)), 'Order table'!$C$3:$C$11))} -> 8 | J3: 1
B4: Pegmatite | D4: 1766 ±1 (Mnz) | G4: Dawn Lake | H4: Annesley et al. 1997 | I4: {=VALUE(_xlfn.XLOOKUP(TRUE, ISNUMBER(SEARCH('Order table'!$B$3:$B$11,Final_table!B2)), 'Order table'!$C$3:$C$11))} -> 1 | J4: 2
B5: Pegmatite | D5: 1788 ±4 (Ttn) | G5: Karpinka Lake | H5: Annesley et al. 1997 | I5: {=VALUE(_xlfn.XLOOKUP(TRUE, ISNUMBER(SEARCH('Order table'!$B$3:$B$11,Final_table!B18)), 'Order table'!$C$3:$C$11))} -> 3 | J5: 2
B6: Metasomatized Pegmatite | D6: 1808 ±4 (Zrn) | G6: East of Black Island | H6: Annesley and Madore, 1997 | I6: {=VALUE(_xlfn.XLOOKUP(TRUE, ISNUMBER(SEARCH('Order table'!$B$3:$B$11,Final_table!B24)), 'Order table'!$C$3:$C$11))} -> 5 | J6: 2
B7: Pegmatite | C7: 1819 ±6 (Zrn) | G7: Greenway Island | H7: Annesley and Madore, 1997 | I7: {=VALUE(_xlfn.XLOOKUP(TRUE, ISNUMBER(SEARCH('Order table'!$B$3:$B$11,Final_table!B23)), 'Order table'!$C$3:$C$11))} -> 5 | J7: 2
B8: Pegmatite | C8: 1811 ±1 (Zrn) | D8: 1805 ±5 (Mnz) | G8: Yalowega Lake | H8: Annesley et al. 1999 | I8: {=VALUE(_xlfn.XLOOKUP(TRUE, ISNUMBER(SEARCH('Order table'!$B$3:$B$11,Final_table!B28)), 'Order table'!$C$3:$C$11))} -> 5 | J8: 2
B9: Granitic pegmatite | C9: 1816 ±7 (Zrn) | D9: 1792.4 ±1.2 (Mnz) | G9: Millenium Deposit | H9: Annesley et al. 2007 | I9: {=VALUE(_xlfn.XLOOKUP(TRUE, ISNUMBER(SEARCH('Order table'!$B$3:$B$11,Final_table!B32)), 'Order table'!$C$3:$C$11))} -> 6 | J9: 2
B10: Pegmatite | C10: 1822 ±5 (Zrn) | D10: 1182 ±7 (Zrn) | G10: Close Lake | H10: Madore et al. 1999 | I10: {=VALUE(_xlfn.XLOOKUP(TRUE, ISNUMBER(SEARCH('Order table'!$B$3:$B$11,Final_table!B30)), 'Order table'!$C$3:$C$11))} -> 6 | J10: 2
B11: Pegmatite | C11: 1819 ±6 (Zrn) | D11: 1224 ±6 (Zrn) | G11: Epp Lake | H11: Madore et al. 1999 | I11: {=VALUE(_xlfn.XLOOKUP(TRUE, ISNUMBER(SEARCH('Order table'!$B$3:$B$11,Final_table!B33)), 'Order table'!$C$3:$C$11))} -> 7 | J11: 2
B12: Granitic pegmatite | C12: 1.8-1.85 Ga (Urn) | G12: Fraser Lake Zone B -Group A | H12: McKechnie et al., 2012 | I12: {=VALUE(_xlfn.XLOOKUP(TRUE, ISNUMBER(SEARCH('Order table'!$B$3:$B$11,Final_table!B50)), 'Order table'!$C$3:$C$11))} -> 8 | J12: 2
B13: Granitic pegmatite | F13: 2.05-2.25 Ga (Mnz) | G13: Fraser Lake Zone B -Group B | H13: McKechnie et al., 2013 | I13: {=VALUE(_xlfn.XLOOKUP(TRUE, ISNUMBER(SEARCH('Order table'!$B$3:$B$11,Final_table!B49)), 'Order table'!$C$3:$C$11))} -> 8 | J13: 2
B14: Pegmatite | C14: 1830 ±5 (Mnz) | G14: Kulyk | H14: McFarlane and McKeough, 2013 | I14: {=VALUE(_xlfn.XLOOKUP(TRUE, ISNUMBER(SEARCH('Order table'!$B$3:$B$11,Final_table!B41)), 'Order table'!$C$3:$C$11))} -> 8 | J14: 2
B15: Granitic pegmatite | C15: 1814.6 ±1.4 (Mnz) | G15: McArthur River | H15: Annesley et al. 2007 | I15: {=VALUE(_xlfn.XLOOKUP(TRUE, ISNUMBER(SEARCH('Order table'!$B$3:$B$11,Final_table!B36)), 'Order table'!$C$3:$C$11))} -> 8 | J15: 2
B16: Pegmatite | C16: 1812 ±2 (Mnz) | G16: P-Patch | H16: Annesley et al. 1999b | I16: {=VALUE(_xlfn.XLOOKUP(TRUE, ISNUMBER(SEARCH('Order table'!$B$3:$B$11,Final_table!B43)), 'Order table'!$C$3:$C$11))} -> 8 | J16: 2
B17: Pegmatite | C17: 1810 ±3 (Mnz) | G17: McClean Lake | H17: Annesley and Madore, 1997 | I17: {=VALUE(_xlfn.XLOOKUP(TRUE, ISNUMBER(SEARCH('Order table'!$B$3:$B$11,Final_table!B46)), 'Order table'!$C$3:$C$11))} -> 8 | J17: 2
B18: Calc-silicate vein | D18: 1789 ±4 (Ttn) | G18: Karpinka Lake | H18: Annesley et al. 1992 | I18: {=VALUE(_xlfn.XLOOKUP(TRUE, ISNUMBER(SEARCH('Order table'!$B$3:$B$11,Final_table!B3)), 'Order table'!$C$3:$C$11))} -> 1 | J18: 3
B19: Calc-silicate Gneiss | D19: 1796 ±4 (Ttn) | G19: Karpinka Lake | H19: Annesley et al. 1997 | I19: {=VALUE(_xlfn.XLOOKUP(TRUE, ISNUMBER(SEARCH('Order table'!$B$3:$B$11,Final_table!B14)), 'Order table'!$C$3:$C$11))} -> 2 | J19: 3
B20: Calc-silicate Gneiss | D20: 1783 ±4 (Ttn) | G20: Karpinka Lake | H20: Annesley et al. 1997 | I20: {=VALUE(_xlfn.XLOOKUP(TRUE, ISNUMBER(SEARCH('Order table'!$B$3:$B$11,Final_table!B4)), 'Order table'!$C$3:$C$11))} -> 2 | J20: 3
B21: Foliated leucotonalite (Trondhjemite) | D21: 1752 ±2 (Ttn) | G21: McClean Lake-Collins Creek | H21: Annesley et al. 1996 | I21: {=VALUE(_xlfn.XLOOKUP(TRUE, ISNUMBER(SEARCH('Order table'!$B$3:$B$11,Final_table!B48)), 'Order table'!$C$3:$C$11))} -> 8 | J21: 4
B22: Grey Granite (sheared) | D22: 1719 ±1 (Zrn) | G22: Hidden Bay | I22: {=VALUE(_xlfn.XLOOKUP(TRUE, ISNUMBER(SEARCH('Order table'!$B$3:$B$11,Final_table!B12)), 'Order table'!$C$3:$C$11))} -> 2 | J22: 5
B23: Porphyritic Granite | C23: 1815 ±2 (Zrn) | D23: 1788 ±2 (Ttn) | G23: Hidden Bay | H23: Annesley et al. 1992 | I23: {=VALUE(_xlfn.XLOOKUP(TRUE, ISNUMBER(SEARCH('Order table'!$B$3:$B$11,Final_table!B7)), 'Order table'!$C$3:$C$11))} -> 2 | J23: 5
B24: Foliated Granite | C24: 2726 ±3 (Zrn) | G24: Fife Island | H24: Annesley et al. 1997 | I24: {=VALUE(_xlfn.XLOOKUP(TRUE, ISNUMBER(SEARCH('Order table'!$B$3:$B$11,Final_table!B21)), 'Order table'!$C$3:$C$11))} -> 4 | J24: 5
B25: Foliated Grey Granite | C25: 1840 ±11 (Zrn) | D25: 1790 ±1 (Mnz) | G25: Greenway Island | H25: Annesley et al. 1997 | I25: {=VALUE(_xlfn.XLOOKUP(TRUE, ISNUMBER(SEARCH('Order table'!$B$3:$B$11,Final_table!B22)), 'Order table'!$C$3:$C$11))} -> 5 | J25: 5
B26: Porphyritic Granite | C26: 1812 ±3 (Zrn) | G26: Harrison Peninsula | H26: Annesley et al. 1995 | I26: {=VALUE(_xlfn.XLOOKUP(TRUE, ISNUMBER(SEARCH('Order table'!$B$3:$B$11,Final_table!B25)), 'Order table'!$C$3:$C$11))} -> 5 | J26: 5
B27: Foliated Granite | C27: 2593 ±5 (Zrn) | D27: 1819 ±2 (Mnz) | G27: Moore - Tomblin | H27: Annesley et al. 1999 | I27: {=VALUE(_xlfn.XLOOKUP(TRUE, ISNUMBER(SEARCH('Order table'!$B$3:$B$11,Final_table!B38)), 'Order table'!$C$3:$C$11))} -> 8 | J27: 5
B28: Foliated Granite | C28: 1818 ±1 (Zrn) | D28: 1783 ±2 (Mnz) | G28: Wheeler River | H28: Annesley et al. 1999 | I28: {=VALUE(_xlfn.XLOOKUP(TRUE, ISNUMBER(SEARCH('Order table'!$B$3:$B$11,Final_table!B52)), 'Order table'!$C$3:$C$11))} -> 8 | J28: 5
B29: Porphyritic granite | C29: 1824 ±3 (Zrn) | G29: Wheeler River | H29: Annesley et al. 1999 | I29: {=VALUE(_xlfn.XLOOKUP(TRUE, ISNUMBER(SEARCH('Order table'!$B$3:$B$11,Final_table!B53)), 'Order table'!$C$3:$C$11))} -> 8 | J29: 5
B30: Meta-gabbro | C30: 1820 ±5 (Zrn) | G30: Hidden Bay | H30: Annesley et al. 1992 | I30: {=VALUE(_xlfn.XLOOKUP(TRUE, ISNUMBER(SEARCH('Order table'!$B$3:$B$11,Final_table!B13)), 'Order table'!$C$3:$C$11))} -> 2 | J30: 6
B31: Monzogabbro | C31: 1828 ±3 (Ttn) | G31: Karpinka Lake | H31: Annesley et al. 1993 | I31: {=VALUE(_xlfn.XLOOKUP(TRUE, ISNUMBER(SEARCH('Order table'!$B$3:$B$11,Final_table!B5)), 'Order table'!$C$3:$C$11))} -> 2 | J31: 6
B32: Monzogabbro | C32: 1828 ±3 (Zrn) | D32: 1795 ±3 (Ttn) | G32: Sandy Islands | H32: Annesley et al. 1995 | I32: {=VALUE(_xlfn.XLOOKUP(TRUE, ISNUMBER(SEARCH('Order table'!$B$3:$B$11,Final_table!B20)), 'Order table'!$C$3:$C$11))} -> 3 | J32: 6
B33: Foliated meta-tonalite | C33: 2612 ±22 (Zrn) | D33: 1803 ±1 (Mnz) | G33: Russel Lake | H33: Annesley et al. 2007 | I33: {=VALUE(_xlfn.XLOOKUP(TRUE, ISNUMBER(SEARCH('Order table'!$B$3:$B$11,Final_table!B39)), 'Order table'!$C$3:$C$11))} -> 8 | J33: 7
B34: Quartz Dioritic Gneiss | C34: 2638 ±65 (Zrn) | D34: 1779 ±2 (Ttn) | G34: Ashley Peninsula | H34: Annesley et al. 1992 | I34: {=VALUE(_xlfn.XLOOKUP(TRUE, ISNUMBER(SEARCH('Order table'!$B$3:$B$11,Final_table!B11)), 'Order table'!$C$3:$C$11))} -> 2 | J34: 8
B35: Tonalitic Gneiss | C35: 2689 ±19 (Zrn) | D35: 1778 ±2 (Ttn) | G35: Ashley Peninsula | H35: Annesley et al. 1991 | I35: {=VALUE(_xlfn.XLOOKUP(TRUE, ISNUMBER(SEARCH('Order table'!$B$3:$B$11,Final_table!B10)), 'Order table'!$C$3:$C$11))} -> 2 | J35: 8
B36: Pelitic Gneiss | D36: 1812 ±2 (Mnz) | G36: Hidden Bay | H36: Annesley et al. 1992 | I36: {=VALUE(_xlfn.XLOOKUP(TRUE, ISNUMBER(SEARCH('Order table'!$B$3:$B$11,Final_table!B8)), 'Order table'!$C$3:$C$11))} -> 2 | J36: 8
B37: Mylonitic Tonalitic Gneiss | C37: 2733 ±9 (Zrn) | G37: Karpinka Lake | H37: Annesley et al. 1992 | I37: {=VALUE(_xlfn.XLOOKUP(TRUE, ISNUMBER(SEARCH('Order table'!$B$3:$B$11,Final_table!B6)), 'Order table'!$C$3:$C$11))} -> 2 | J37: 8
B38: Granodioritic Gneiss | D38: 1792 ±4 (Ttn) | G38: Karpinka Lake | H38: Annesley et al. 1997 | I38: {=VALUE(_xlfn.XLOOKUP(TRUE, ISNUMBER(SEARCH('Order table'!$B$3:$B$11,Final_table!B15)), 'Order table'!$C$3:$C$11))} -> 2 | J38: 8
B39: Metasomatized Orthogneiss | D39: 1803 ±4 (Ttn) | G39: Karpinka Lake | H39: Annesley et al. 1997 | I39: {=VALUE(_xlfn.XLOOKUP(TRUE, ISNUMBER(SEARCH('Order table'!$B$3:$B$11,Final_table!B17)), 'Order table'!$C$3:$C$11))} -> 2 | J39: 8
B40: Silicified granitic Gneiss | C40: 2594 ±10 (Zrn) | D40: 1806 ±2 (Mnz) | G40: Karpinka Lake | H40: Annesley et al. 1997 | I40: {=VALUE(_xlfn.XLOOKUP(TRUE, ISNUMBER(SEARCH('Order table'!$B$3:$B$11,Final_table!B16)), 'Order table'!$C$3:$C$11))} -> 2 | J40: 8
...

Sheet others
A1: Lithology | B1: Crystallization age | C1: Metamorphic age | D1: Area | E1: Reference
A2: Psammo pelitic gneiss | B2: 1880 Urn | C2: 1730-1770 Urn | D2: Karpinka Lake | E2: Williams-Jonnes & Sawiuk 1985
A3: Pelitic anatectites (Pegmatites) | B3: 1966 - 1858 | D3: Karin Lake | E3: Parslow et al. 1985
A4: Tonalite gneiss | B4: 2780 Zrn | C4: 1800 Zrn | D4: Black Birch Lake | E4: Orell et al. 1999
A5: Augen Gneiss | B5: 2660-2628 Zrn | D5: Black Birch Lake
A6: Quartzite–metapelite* | B6: 2134 - 2580 Zrn* | C6: 1880-1769 Mnz | D6: Black Birch Lake
A7: Qtz–Feldspar gneiss | B7: 2614-1977 Zrn | C7: 1804 Mnz | D7: Black Birch Lake
A8: Mafic gneiss | B8: 1802 ± 6 Zrn | C8: 1809 Zrn | D8: Black Birch Lake
A9: Peraluminos granite dike | B9: 1807 | C9: 1787 | D9: Black Birch Lake | E9: Orell et al. 1999
A10: Granite pegmatitic dike | B10: 1805 ± 1 | D10: Black Birch Lake | E10: Orell et al. 1999
A11: Leucogranite | B11: 1804 Mnz | C11: 1703 | D11: Black Birch Lake | E11: Orell et al. 1999

Sheet Order table
B2: Rock | C2: #
B3: U vein | C3: 1
B4: Pegmatite | C4: 2
B5: Calc-silicate | C5: 3
B6: Foliated leucotonalite (Trondhjemite) | C6: 4
B7: Granite | C7: 5
B8: Monzogabbro | C8: 6
B9: Foliated meta-tonalite | C9: 7
B10: Gneis | C10: 8
B11: Meta-gabbro | C11: =+C8 -> 6

Sheet Xlookup_table
B1: Sample ID | C1: Rock | D1: Crystallization age | E1: Metamorphic age | F1: Hudsonian metamorphism | G1: Inherited age | H1: Area | I1: Reference
B2: A230 | C2: =_xlfn.XLOOKUP(B2,No_duplicates!$A$2:$A$110,No_duplicates!$B$2:$B$110,"") -> Pegmatite | D2: {=_xlfn.XLOOKUP(1,('Working table'!$B$2:$B$100=Xlookup_table!$B2)*('Working table'!$M$2:$M$100=Xlookup_table!D$1),'Working table'!$L$2:$L$100,"")} | E2: {=_xlfn.XLOOKUP(1,('Working table'!$B$2:$B$100=Xlookup_table!$B2)*('Working table'!$M$2:$M$100=Xlookup_table!E$1),'Working table'!$L$2:$L$100,"")} -> 1766 ±1 (Xtm) | F2: {=_xlfn.XLOOKUP(1,('Working table'!$B$2:$B$98=Xlookup_table!$B2)*('Working table'!$M$2:$M$98=Xlookup_table!F$1),'Working table'!$L$2:$L$98,"")} | G2: {=_xlfn.XLOOKUP(1,('Working table'!$B$2:$B$98=Xlookup_table!$B2)*('Working table'!$M$2:$M$98=Xlookup_table!G$1),'Working table'!$L$2:$L$98,"")} | H2: =_xlfn.XLOOKUP(B2,No_duplicates!$A$2:$A$110,No_duplicates!$C$2:$C$110,"") -> Dawn Lake | I2: =IF(_xlfn.XLOOKUP(B2,No_duplicates!$A$2:$A$110,No_duplicates!$D$2:$D$110,"")=0,"",_xlfn.XLOOKUP(B2,No_duplicates!$A$2:$A$110,No_duplicates!$D$2:$D$110)) -> Annesley et al. 1997
B3: A88-036 | C3: =_xlfn.XLOOKUP(B3,No_duplicates!$A$2:$A$110,No_duplicates!$B$2:$B$110,"") -> Calc-silicate vein | D3: {=_xlfn.XLOOKUP(1,('Working table'!$B$2:$B$100=Xlookup_table!$B3)*('Working table'!$M$2:$M$100=Xlookup_table!D$1),'Working table'!$L$2:$L$100,"")} | E3: {=_xlfn.XLOOKUP(1,('Working table'!$B$2:$B$100=Xlookup_table!$B3)*('Working table'!$M$2:$M$100=Xlookup_table!E$1),'Working table'!$L$2:$L$100,"")} -> 1789 ±4 (Ttn) | F3: {=_xlfn.XLOOKUP(1,('Working table'!$B$2:$B$98=Xlookup_table!$B3)*('Working table'!$M$2:$M$98=Xlookup_table!F$1),'Working table'!$L$2:$L$98,"")} | G3: {=_xlfn.XLOOKUP(1,('Working table'!$B$2:$B$98=Xlookup_table!$B3)*('Working table'!$M$2:$M$98=Xlookup_table!G$1),'Working table'!$L$2:$L$98,"")} | H3: =_xlfn.XLOOKUP(B3,No_duplicates!$A$2:$A$110,No_duplicates!$C$2:$C$110,"") -> Karpinka Lake | I3: =IF(_xlfn.XLOOKUP(B3,No_duplicates!$A$2:$A$110,No_duplicates!$D$2:$D$110,"")=0,"",_xlfn.XLOOKUP(B3,No_duplicates!$A$2:$A$110,No_duplicates!$D$2:$D$110)) -> Annesley et al. 1992
B4: A88-042 | C4: =_xlfn.XLOOKUP(B4,No_duplicates!$A$2:$A$110,No_duplicates!$B$2:$B$110,"") -> Calc-silicate Gneiss | D4: {=_xlfn.XLOOKUP(1,('Working table'!$B$2:$B$100=Xlookup_table!$B4)*('Working table'!$M$2:$M$100=Xlookup_table!D$1),'Working table'!$L$2:$L$100,"")} | E4: {=_xlfn.XLOOKUP(1,('Working table'!$B$2:$B$100=Xlookup_table!$B4)*('Working table'!$M$2:$M$100=Xlookup_table!E$1),'Working table'!$L$2:$L$100,"")} -> 1783 ±4 (Ttn) | F4: {=_xlfn.XLOOKUP(1,('Working table'!$B$2:$B$98=Xlookup_table!$B4)*('Working table'!$M$2:$M$98=Xlookup_table!F$1),'Working table'!$L$2:$L$98,"")} | G4: {=_xlfn.XLOOKUP(1,('Working table'!$B$2:$B$98=Xlookup_table!$B4)*('Working table'!$M$2:$M$98=Xlookup_table!G$1),'Working table'!$L$2:$L$98,"")} | H4: =_xlfn.XLOOKUP(B4,No_duplicates!$A$2:$A$110,No_duplicates!$C$2:$C$110,"") -> Karpinka Lake | I4: =IF(_xlfn.XLOOKUP(B4,No_duplicates!$A$2:$A$110,No_duplicates!$D$2:$D$110,"")=0,"",_xlfn.XLOOKUP(B4,No_duplicates!$A$2:$A$110,No_duplicates!$D$2:$D$110)) -> Annesley et al. 1997
B5: A88-043 | C5: =_xlfn.XLOOKUP(B5,No_duplicates!$A$2:$A$110,No_duplicates!$B$2:$B$110,"") -> Monzogabbro | D5: {=_xlfn.XLOOKUP(1,('Working table'!$B$2:$B$100=Xlookup_table!$B5)*('Working table'!$M$2:$M$100=Xlookup_table!D$1),'Working table'!$L$2:$L$100,"")} -> 1828 ±3 (Ttn) | E5: {=_xlfn.XLOOKUP(1,('Working table'!$B$2:$B$100=Xlookup_table!$B5)*('Working table'!$M$2:$M$100=Xlookup_table!E$1),'Working table'!$L$2:$L$100,"")} | F5: {=_xlfn.XLOOKUP(1,('Working table'!$B$2:$B$98=Xlookup_table!$B5)*('Working table'!$M$2:$M$98=Xlookup_table!F$1),'Working table'!$L$2:$L$98,"")} | G5: {=_xlfn.XLOOKUP(1,('Working table'!$B$2:$B$98=Xlookup_table!$B5)*('Working table'!$M$2:$M$98=Xlookup_table!G$1),'Working table'!$L$2:$L$98,"")} | H5: =_xlfn.XLOOKUP(B5,No_duplicates!$A$2:$A$110,No_duplicates!$C$2:$C$110,"") -> Karpinka Lake | I5: =IF(_xlfn.XLOOKUP(B5,No_duplicates!$A$2:$A$110,No_duplicates!$D$2:$D$110,"")=0,"",_xlfn.XLOOKUP(B5,No_duplicates!$A$2:$A$110,No_duplicates!$D$2:$D$110)) -> Annesley et al. 1993
B6: A88-052 | C6: =_xlfn.XLOOKUP(B6,No_duplicates!$A$2:$A$110,No_duplicates!$B$2:$B$110,"") -> Mylonitic Tonalitic Gneiss | D6: {=_xlfn.XLOOKUP(1,('Working table'!$B$2:$B$100=Xlookup_table!$B6)*('Working table'!$M$2:$M$100=Xlookup_table!D$1),'Working table'!$L$2:$L$100,"")} -> 2733 ±9 (Xtm) | E6: {=_xlfn.XLOOKUP(1,('Working table'!$B$2:$B$100=Xlookup_table!$B6)*('Working table'!$M$2:$M$100=Xlookup_table!E$1),'Working table'!$L$2:$L$100,"")} | F6: {=_xlfn.XLOOKUP(1,('Working table'!$B$2:$B$98=Xlookup_table!$B6)*('Working table'!$M$2:$M$98=Xlookup_table!F$1),'Working table'!$L$2:$L$98,"")} | G6: {=_xlfn.XLOOKUP(1,('Working table'!$B$2:$B$98=Xlookup_table!$B6)*('Working table'!$M$2:$M$98=Xlookup_table!G$1),'Working table'!$L$2:$L$98,"")} | H6: =_xlfn.XLOOKUP(B6,No_duplicates!$A$2:$A$110,No_duplicates!$C$2:$C$110,"") -> Karpinka Lake | I6: =IF(_xlfn.XLOOKUP(B6,No_duplicates!$A$2:$A$110,No_duplicates!$D$2:$D$110,"")=0,"",_xlfn.XLOOKUP(B6,No_duplicates!$A$2:$A$110,No_duplicates!$D$2:$D$110)) -> Annesley et al. 1992
B7: A89-100 | C7: =_xlfn.XLOOKUP(B7,No_duplicates!$A$2:$A$110,No_duplicates!$B$2:$B$110,"") -> Porphyritic Granite | D7: {=_xlfn.XLOOKUP(1,('Working table'!$B$2:$B$100=Xlookup_table!$B7)*('Working table'!$M$2:$M$100=Xlookup_table!D$1),'Working table'!$L$2:$L$100,"")} -> 1815 ±2 (Xtm) | E7: {=_xlfn.XLOOKUP(1,('Working table'!$B$2:$B$100=Xlookup_table!$B7)*('Working table'!$M$2:$M$100=Xlookup_table!E$1),'Working table'!$L$2:$L$100,"")} -> 1788 ±2 (Xtm) | F7: {=_xlfn.XLOOKUP(1,('Working table'!$B$2:$B$98=Xlookup_table!$B7)*('Working table'!$M$2:$M$98=Xlookup_table!F$1),'Working table'!$L$2:$L$98,"")} | G7: {=_xlfn.XLOOKUP(1,('Working table'!$B$2:$B$98=Xlookup_table!$B7)*('Working table'!$M$2:$M$98=Xlookup_table!G$1),'Working table'!$L$2:$L$98,"")} | H7: =_xlfn.XLOOKUP(B7,No_duplicates!$A$2:$A$110,No_duplicates!$C$2:$C$110,"") -> Hidden Bay | I7: =IF(_xlfn.XLOOKUP(B7,No_duplicates!$A$2:$A$110,No_duplicates!$D$2:$D$110,"")=0,"",_xlfn.XLOOKUP(B7,No_duplicates!$A$2:$A$110,No_duplicates!$D$2:$D$110)) -> Annesley et al. 1992
B8: A89-108 | C8: =_xlfn.XLOOKUP(B8,No_duplicates!$A$2:$A$110,No_duplicates!$B$2:$B$110,"") -> Pelitic Gneiss | D8: {=_xlfn.XLOOKUP(1,('Working table'!$B$2:$B$100=Xlookup_table!$B8)*('Working table'!$M$2:$M$100=Xlookup_table!D$1),'Working table'!$L$2:$L$100,"")} | E8: {=_xlfn.XLOOKUP(1,('Working table'!$B$2:$B$100=Xlookup_table!$B8)*('Working table'!$M$2:$M$100=Xlookup_table!E$1),'Working table'!$L$2:$L$100,"")} -> 1812 ±2 (Xtm) | F8: {=_xlfn.XLOOKUP(1,('Working table'!$B$2:$B$98=Xlookup_table!$B8)*('Working table'!$M$2:$M$98=Xlookup_table!F$1),'Working table'!$L$2:$L$98,"")} | G8: {=_xlfn.XLOOKUP(1,('Working table'!$B$2:$B$98=Xlookup_table!$B8)*('Working table'!$M$2:$M$98=Xlookup_table!G$1),'Working table'!$L$2:$L$98,"")} | H8: =_xlfn.XLOOKUP(B8,No_duplicates!$A$2:$A$110,No_duplicates!$C$2:$C$110,"") -> Hidden Bay | I8: =IF(_xlfn.XLOOKUP(B8,No_duplicates!$A$2:$A$110,No_duplicates!$D$2:$D$110,"")=0,"",_xlfn.XLOOKUP(B8,No_duplicates!$A$2:$A$110,No_duplicates!$D$2:$D$110)) -> Annesley et al. 1992
B9: A89-116 | C9: =_xlfn.XLOOKUP(B9,No_duplicates!$A$2:$A$110,No_duplicates!$B$2:$B$110,"") -> Granodioritic Gneiss | D9: {=_xlfn.XLOOKUP(1,('Working table'!$B$2:$B$100=Xlookup_table!$B9)*('Working table'!$M$2:$M$100=Xlookup_table!D$1),'Working table'!$L$2:$L$100,"")} -> 2620 ±10 (Xtm) | E9: {=_xlfn.XLOOKUP(1,('Working table'!$B$2:$B$100=Xlookup_table!$B9)*('Working table'!$M$2:$M$100=Xlookup_table!E$1),'Working table'!$L$2:$L$100,"")} -> 1798 ±14 (Xtm) | F9: {=_xlfn.XLOOKUP(1,('Working table'!$B$2:$B$98=Xlookup_table!$B9)*('Working table'!$M$2:$M$98=Xlookup_table!F$1),'Working table'!$L$2:$L$98,"")} | G9: {=_xlfn.XLOOKUP(1,('Working table'!$B$2:$B$98=Xlookup_table!$B9)*('Working table'!$M$2:$M$98=Xlookup_table!G$1),'Working table'!$L$2:$L$98,"")} | H9: =_xlfn.XLOOKUP(B9,No_duplicates!$A$2:$A$110,No_duplicates!$C$2:$C$110,"") -> SE Rabbit Lake | I9: =IF(_xlfn.XLOOKUP(B9,No_duplicates!$A$2:$A$110,No_duplicates!$D$2:$D$110,"")=0,"",_xlfn.XLOOKUP(B9,No_duplicates!$A$2:$A$110,No_duplicates!$D$2:$D$110)) -> Annesley et al. 1992
B10: A90-005b | C10: =_xlfn.XLOOKUP(B10,No_duplicates!$A$2:$A$110,No_duplicates!$B$2:$B$110,"") -> Tonalitic Gneiss | D10: {=_xlfn.XLOOKUP(1,('Working table'!$B$2:$B$100=Xlookup_table!$B10)*('Working table'!$M$2:$M$100=Xlookup_table!D$1),'Working table'!$L$2:$L$100,"")} -> 2689 ±19 (Xtm) | E10: {=_xlfn.XLOOKUP(1,('Working table'!$B$2:$B$100=Xlookup_table!$B10)*('Working table'!$M$2:$M$100=Xlookup_table!E$1),'Working table'!$L$2:$L$100,"")} -> 1778 ±2 (Xtm) | F10: {=_xlfn.XLOOKUP(1,('Working table'!$B$2:$B$98=Xlookup_table!$B10)*('Working table'!$M$2:$M$98=Xlookup_table!F$1),'Working table'!$L$2:$L$98,"")} | G10: {=_xlfn.XLOOKUP(1,('Working table'!$B$2:$B$98=Xlookup_table!$B10)*('Working table'!$M$2:$M$98=Xlookup_table!G$1),'Working table'!$L$2:$L$98,"")} | H10: =_xlfn.XLOOKUP(B10,No_duplicates!$A$2:$A$110,No_duplicates!$C$2:$C$110,"") -> Ashley Peninsula | I10: =IF(_xlfn.XLOOKUP(B10,No_duplicates!$A$2:$A$110,No_duplicates!$D$2:$D$110,"")=0,"",_xlfn.XLOOKUP(B10,No_duplicates!$A$2:$A$110,No_duplicates!$D$2:$D$110)) -> Annesley et al. 1991
B11: A90-006 | C11: =_xlfn.XLOOKUP(B11,No_duplicates!$A$2:$A$110,No_duplicates!$B$2:$B$110,"") -> Quartz Dioritic Gneiss | D11: {=_xlfn.XLOOKUP(1,('Working table'!$B$2:$B$100=Xlookup_table!$B11)*('Working table'!$M$2:$M$100=Xlookup_table!D$1),'Working table'!$L$2:$L$100,"")} -> 2638 ±65 (Xtm) | E11: {=_xlfn.XLOOKUP(1,('Working table'!$B$2:$B$100=Xlookup_table!$B11)*('Working table'!$M$2:$M$100=Xlookup_table!E$1),'Working table'!$L$2:$L$100,"")} -> 1779 ±2 (Xtm) | F11: {=_xlfn.XLOOKUP(1,('Working table'!$B$2:$B$98=Xlookup_table!$B11)*('Working table'!$M$2:$M$98=Xlookup_table!F$1),'Working table'!$L$2:$L$98,"")} | G11: {=_xlfn.XLOOKUP(1,('Working table'!$B$2:$B$98=Xlookup_table!$B11)*('Working table'!$M$2:$M$98=Xlookup_table!G$1),'Working table'!$L$2:$L$98,"")} | H11: =_xlfn.XLOOKUP(B11,No_duplicates!$A$2:$A$110,No_duplicates!$C$2:$C$110,"") -> Ashley Peninsula | I11: =IF(_xlfn.XLOOKUP(B11,No_duplicates!$A$2:$A$110,No_duplicates!$D$2:$D$110,"")=0,"",_xlfn.XLOOKUP(B11,No_duplicates!$A$2:$A$110,No_duplicates!$D$2:$D$110)) -> Annesley et al. 1992
B12: A90-011b | C12: =_xlfn.XLOOKUP(B12,No_duplicates!$A$2:$A$110,No_duplicates!$B$2:$B$110,"") -> Grey Granite (sheared) | D12: {=_xlfn.XLOOKUP(1,('Working table'!$B$2:$B$100=Xlookup_table!$B12)*('Working table'!$M$2:$M$100=Xlookup_table!D$1),'Working table'!$L$2:$L$100,"")} | E12: {=_xlfn.XLOOKUP(1,('Working table'!$B$2:$B$100=Xlookup_table!$B12)*('Working table'!$M$2:$M$100=Xlookup_table!E$1),'Working table'!$L$2:$L$100,"")} -> 1719 ±1 (Xtm) | F12: {=_xlfn.XLOOKUP(1,('Working table'!$B$2:$B$98=Xlookup_table!$B12)*('Working table'!$M$2:$M$98=Xlookup_table!F$1),'Working table'!$L$2:$L$98,"")} | G12: {=_xlfn.XLOOKUP(1,('Working table'!$B$2:$B$98=Xlookup_table!$B12)*('Working table'!$M$2:$M$98=Xlookup_table!G$1),'Working table'!$L$2:$L$98,"")} | H12: =_xlfn.XLOOKUP(B12,No_duplicates!$A$2:$A$110,No_duplicates!$C$2:$C$110,"") -> Hidden Bay | I12: =IF(_xlfn.XLOOKUP(B12,No_duplicates!$A$2:$A$110,No_duplicates!$D$2:$D$110,"")=0,"",_xlfn.XLOOKUP(B12,No_duplicates!$A$2:$A$110,No_duplicates!$D$2:$D$110))
B13: A90-012a | C13: =_xlfn.XLOOKUP(B13,No_duplicates!$A$2:$A$110,No_duplicates!$B$2:$B$110,"") -> Meta-gabbro | D13: {=_xlfn.XLOOKUP(1,('Working table'!$B$2:$B$100=Xlookup_table!$B13)*('Working table'!$M$2:$M$100=Xlookup_table!D$1),'Working table'!$L$2:$L$100,"")} -> 1820 ±5 (Xtm) | E13: {=_xlfn.XLOOKUP(1,('Working table'!$B$2:$B$100=Xlookup_table!$B13)*('Working table'!$M$2:$M$100=Xlookup_table!E$1),'Working table'!$L$2:$L$100,"")} | F13: {=_xlfn.XLOOKUP(1,('Working table'!$B$2:$B$98=Xlookup_table!$B13)*('Working table'!$M$2:$M$98=Xlookup_table!F$1),'Working table'!$L$2:$L$98,"")} | G13: {=_xlfn.XLOOKUP(1,('Working table'!$B$2:$B$98=Xlookup_table!$B13)*('Working table'!$M$2:$M$98=Xlookup_table!G$1),'Working table'!$L$2:$L$98,"")} | H13: =_xlfn.XLOOKUP(B13,No_duplicates!$A$2:$A$110,No_duplicates!$C$2:$C$110,"") -> Hidden Bay | I13: =IF(_xlfn.XLOOKUP(B13,No_duplicates!$A$2:$A$110,No_duplicates!$D$2:$D$110,"")=0,"",_xlfn.XLOOKUP(B13,No_duplicates!$A$2:$A$110,No_duplicates!$D$2:$D$110)) -> Annesley et al. 1992
... B53: ZM-08-02 | C53: =_xlfn.XLOOKUP(B53,No_duplicates!$A$2:$A$110,No_duplicates!$B$2:$B$110,"") -> Porphyritic granite | D53: {=_xlfn.XLOOKUP(1,('Working table'!$B$2:$B$100=Xlookup_table!$B53)*('Working table'!$M$2:$M$100=Xlookup_table!D$1),'Working table'!$L$2:$L$100,"")} -> 1824 ±3 (Ttn) | E53: {=_xlfn.XLOOKUP(1,('Working table'!$B$2:$B$100=Xlookup_table!$B53)*('Working table'!$M$2:$M$100=Xlookup_table!E$1),'Working table'!$L$2:$L$100,"")} | F53: {=_xlfn.XLOOKUP(1,('Working table'!$B$2:$B$98=Xlookup_table!$B53)*('Working table'!$M$2:$M$98=Xlookup_table!F$1),'Working table'!$L$2:$L$98,"")} | G53: {=_xlfn.XLOOKUP(1,('Working table'!$B$2:$B$98=Xlookup_table!$B53)*('Working table'!$M$2:$M$98=Xlookup_table!G$1),'Working table'!$L$2:$L$98,"")} | H53: =_xlfn.XLOOKUP(B53,No_duplicates!$A$2:$A$110,No_duplicates!$C$2:$C$110,"") -> Wheeler River | I53: =IF(_xlfn.XLOOKUP(B53,No_duplicates!$A$2:$A$110,No_duplicates!$D$2:$D$110,"")=0,"",_xlfn.XLOOKUP(B53,No_duplicates!$A$2:$A$110,No_duplicates!$D$2:$D$110)) -> Annesley et al. 1999
B54: MAC-257-1 | C54: =_xlfn.XLOOKUP(B54,No_duplicates!$A$2:$A$110,No_duplicates!$B$2:$B$110,"") -> Leucogranite | D54: {=_xlfn.XLOOKUP(1,('Working table'!$B$2:$B$100=Xlookup_table!$B54)*('Working table'!$M$2:$M$100=Xlookup_table!D$1),'Working table'!$L$2:$L$100,"")} -> 1816 ±1 (Xtm) | E54: {=_xlfn.XLOOKUP(1,('Working table'!$B$2:$B$100=Xlookup_table!$B54)*('Working table'!$M$2:$M$100=Xlookup_table!E$1),'Working table'!$L$2:$L$100,"")} | H54: =_xlfn.XLOOKUP(B54,No_duplicates!$A$2:$A$110,No_duplicates!$C$2:$C$110,"") -> McArthur River | I54: =IF(_xlfn.XLOOKUP(B54,No_duplicates!$A$2:$A$110,No_duplicates!$D$2:$D$110,"")=0,"",_xlfn.XLOOKUP(B54,No_duplicates!$A$2:$A$110,No_duplicates!$D$2:$D$110)) -> Annesley et al. 2007

Sheet Unique_values
B2: Unique Value/Sample | C2: Unique Value/interpretation
B3: {=_xlfn.UNIQUE('Working table'!B2:B101)} -> CX-28 | C3: {=_xlfn.UNIQUE('Working table'!M2:M98)} -> Metamorphic age | F3: Metamorphic age | G3: Crystallization age | H3: Detrital age | I3: Hudsonian metamorphism (lower intercept) | J3: Inherited age
B4: A88-042 | C4: Crystallization age | F4: Metamorphic age | G4: Crystallization age | H4: Detrital age | I4: Hudsonian metamorphism (lower intercept) | J4: Inherited age
B5: A91-015 | C5: Hudsonian metamorphism | F5: Metamorphic age | G5: Crystallization age | H5: Detrital age | I5: Hudsonian metamorphism (lower intercept) | J5: Inherited age
B6: A88-036 | C6: Inherited age | F6: Metamorphic age | G6: Crystallization age | H6: Detrital age | I6: Hudsonian metamorphism (lower intercept) | J6: Inherited age
B7: A93-036 | C7: Detrital age | F7: Metamorphic age | G7: Crystallization age | H7: Detrital age | I7: Hudsonian metamorphism (lower intercept) | J7: Inherited age
B8: MT-18 | C8: 0
B9: ZM-08
B10: A93-037a
B11: ST-1
B12: NN-2
B13: A94-051
B14: MAC-65
B15: NN-4
B16: CX-30
B17: MAC-257
B18: WYL-09-46
B19: WYL-10-62
B20: A89-116
... B45: A91-014
B46: 0
B47: A89-100
B48: A94-040a
B49: ZM-08-02
B50: A90-006
B51: A92-056a
B52: A92-007b1
B53: A90-005b
B54: CLC1-123
B55: PVS-9
B56: S-566
B57: JM-2
B58: JM-3

Sheet No_duplicates
A1: Sample | B1: Rock | C1: Area | D1: Reference | E1: Reference2
A2: A230 | B2: Pegmatite | C2: Dawn Lake | D2: Annesley et al. 1997
A3: A88-036 | B3: Calc-silicate vein | C3: Karpinka Lake | D3: Annesley et al. 1992
A4: A88-042 | B4: Calc-silicate Gneiss | C4: Karpinka Lake | D4: Annesley et al. 1997
A5: A88-043 | B5: Monzogabbro | C5: Karpinka Lake | D5: Annesley et al. 1993
A6: A88-052 | B6: Mylonitic Tonalitic Gneiss | C6: Karpinka Lake | D6: Annesley et al. 1992
A7: A89-100 | B7: Porphyritic Granite | C7: Hidden Bay | D7: Annesley et al. 1992
A8: A89-108 | B8: Pelitic Gneiss | C8: Hidden Bay | D8: Annesley et al. 1992
A9: A89-114 | B9: Meta-quartzite | C9: Hidden Bay | D9: Annesley et al. 1992
A10: A89-116 | B10: Granodioritic Gneiss | C10: SE Rabbit Lake | D10: Annesley et al. 1992
A11: A90-005b | B11: Tonalitic Gneiss | C11: Ashley Peninsula | D11: Annesley et al. 1991
A12: A90-006 | B12: Quartz Dioritic Gneiss | C12: Ashley Peninsula | D12: Annesley et al. 1992
A13: A90-011b | B13: Grey Granite (sheared) | C13: Hidden Bay
A14: A90-012a | B14: Meta-gabbro | C14: Hidden Bay | D14: Annesley et al. 1992
A15: A91-014 | B15: Pelitic gneiss | C15: Karpinka Lake | D15: Annesley et al. 1992
A16: A91-015 | B16: Calc-silicate Gneiss | C16: Karpinka Lake | D16: Annesley et al. 1997
A17: A92-002b | B17: Granodioritic Gneiss | C17: Karpinka Lake | D17: Annesley et al. 1997
A18: A92-007b1 | B18: Silicified granitic Gneiss | C18: Karpinka Lake | D18: Annesley et al. 1997
A19: A92-011c | B19: Metasomatized Orthogneiss | C19: Karpinka Lake | D19: Annesley et al. 1997
A20: A92-045 | B20: Pegmatite | C20: Karpinka Lake | D20: Annesley et al. 1997
A21: A92-056a | B21: Retrogessed Tonalitic Gneiss | C21: Karpinka Lake | D21: Annesley et al. 1997
A22: A93-026a | B22: Monzogabbro | C22: Sandy Islands | D22: Annesley et al. 1995
A23: A93-036 | B23: Foliated Granite | C23: Fife Island | D23: Annesley et al. 1997
A24: A93-037a | B24: Foliated Grey Granite | C24: Greenway Island | D24: Annesley et al. 1997
A25: A93-037b | B25: Pegmatite | C25: Greenway Island | D25: Annesley and Madore, 1997
... A56: MAC-257-1 | B56: Leucogranite | C56: McArthur River | D56: Annesley et al. 2007

Sheet Working table
A1: Map | B1: Sample | C1: Rock | D1: System | E1: Technique | F1: Mineral | G1: Min_label | H1: Age | I1: Analytical/Internal uncertainty (X) | J1: Error | K1: Age + error | L1: Age + error + min | M1: Interpretation | N1: Sample type | O1: Depth | P1: Area | Q1: longitute | R1: Latitute2 | S1: UTM E | T1: UTM N | U1: Column4 | V1: Column5 | W1: Column6
B2: CX-28 | C2: Archean granitic gneiss | D2: U-Pb | E2: ID-TIMS | F2: Monazite | G2: =IF('Working table'!$F58=$X$2,$Y$2,IF('Working table'!$F58=$X$3,$Y$3,IF('Working table'!$F58=$X$4,$Y$4,IF('Working table'!$F58=$X$5,$Y$5,$Y$6)))) -> Xtm | H2: 1791.3 | I2: +8/-7 | J2: ±8 | K2: =H2 & " " & J2 -> 1791.3 ±8 | L2: =H2&" "&J2&" "&"("&G2&")" -> 1791.3 ±8 (Xtm) | M2: Metamorphic age | N2: Drill core | O2: 760.25-760.50 | P2: Millenium Deposit | U2: Annesley et al. 2007
B3: CX-28 | C3: Archean granitic gneiss | D3: U-Pb | E3: ID-TIMS | F3: Zircon | G3: =IF('Working table'!$F59=$X$2,$Y$2,IF('Working table'!$F59=$X$3,$Y$3,IF('Working table'!$F59=$X$4,$Y$4,IF('Working table'!$F59=$X$5,$Y$5,$Y$6)))) -> Xtm | H3: 2731 | I3: 25 | J3: ±25 | K3: =H3 & " " & J3 -> 2731 ±25 | L3: =H3&" "&J3&" "&"("&G3&")" -> 2731 ±25 (Xtm) | M3: Crystallization age | N3: Drill core | O3: 760.25-760.50 | P3: Millenium Deposit | U3: Annesley et al. 2007
A4: 99-4.2-(9.1) | B4: A88-042 | C4: Calc-silicate Gneiss | D4: U-Pb | E4: TIMS | F4: Titanite | G4: =IF('Working table'!$F5=$X$2,$Y$2,IF('Working table'!$F5=$X$3,$Y$3,IF('Working table'!$F5=$X$4,$Y$4,IF('Working table'!$F5=$X$5,$Y$5,$Y$6)))) -> Ttn | H4: 1783 | I4: 4 | J4: ±4 | K4: =H4 & " " & J4 -> 1783 ±4 | L4: =H4&" "&J4&" "&"("&G4&")" -> 1783 ±4 (Ttn) | M4: Metamorphic age | N4: Outcrop | P4: Karpinka Lake | Q4: -106.12139 | R4: 56.933056 | S4: 431695 | T4: 6308856 | U4: Annesley et al. 1997 | X4: Titanite | Y4: Ttn
A5: 99-4.2-(9.1) | B5: A91-015 | C5: Calc-silicate Gneiss | D5: U-Pb | E5: TIMS | F5: Titanite | G5: =IF('Working table'!$F27=$X$2,$Y$2,IF('Working table'!$F27=$X$3,$Y$3,IF('Working table'!$F27=$X$4,$Y$4,IF('Working table'!$F27=$X$5,$Y$5,$Y$6)))) -> Xtm | H5: 1796 | I5: 4 | J5: ±4 | K5: =H5 & " " & J5 -> 1796 ±4 | L5: =H5&" "&J5&" "&"("&G5&")" -> 1796 ±4 (Xtm) | M5: Metamorphic age | N5: Outcrop | P5: Karpinka Lake | Q5: -106.13444 | R5: 56.933056 | S5: 430929 | T5: 6310520 | U5: Annesley et al. 1997
A6: 99-4.2-(9.1) | B6: A88-036 | C6: Calc-silicate vein | D6: U-Pb | E6: TIMS | F6: Titanite | G6: =IF('Working table'!$F4=$X$2,$Y$2,IF('Working table'!$F4=$X$3,$Y$3,IF('Working table'!$F4=$X$4,$Y$4,IF('Working table'!$F4=$X$5,$Y$5,$Y$6)))) -> Ttn | H6: 1789 | I6: 4 | J6: ±4 | K6: =H6 & " " & J6 -> 1789 ±4 | L6: =H6&" "&J6&" "&"("&G6&")" -> 1789 ±4 (Ttn) | M6: Metamorphic age | N6: Outcrop | P6: Karpinka Lake | Q6: -106.15278 | R6: 56.831389 | S6: 429777 | T6: 6299228 | U6: Annesley et al. 1992 | X6: Xenotime | Y6: Xtm
A7: 99-4.2-(9.2) | B7: A93-036 | C7: Foliated Granite | D7: U-Pb | E7: TIMS | F7: Zircon | G7: =IF('Working table'!$F40=$X$2,$Y$2,IF('Working table'!$F40=$X$3,$Y$3,IF('Working table'!$F40=$X$4,$Y$4,IF('Working table'!$F40=$X$5,$Y$5,$Y$6)))) -> Xtm | H7: 2726 | I7: 5 | J7: ±3 | K7: =H7 & " " & J7 -> 2726 ±3 | L7: =H7&" "&J7&" "&"("&G7&")" -> 2726 ±3 (Xtm) | M7: Crystallization age | N7: Outcrop | P7: Fife Island | Q7: -103.3525 | R7: 58.42 | S7: 596240 | T7: 6476663 | U7: Annesley et al. 1997
A8: 99-4.2-(9.1) | B8: MT-18 | C8: Foliated Granite | D8: U-Pb | E8: TIMS | F8: Zircon | G8: =IF('Working table'!$F69=$X$2,$Y$2,IF('Working table'!$F69=$X$3,$Y$3,IF('Working table'!$F69=$X$4,$Y$4,IF('Working table'!$F69=$X$5,$Y$5,$Y$6)))) -> Xtm | H8: 2593 | I8: 5 | J8: ±5 | K8: =H8 & " " & J8 -> 2593 ±5 | L8: =H8&" "&J8&" "&"("&G8&")" -> 2593 ±5 (Xtm) | M8: Crystallization age | N8: Drill core | O8: 356.0-365.4 or 364.2-364.7 | P8: Moore - Tomblin | Q8: -105.05306 | R8: 57.47 | S8: 496791 | T8: 6369707 | U8: Annesley et al. 1999
A9: 99-4.2-(9.1) | B9: MT-18 | C9: Foliated Granite | D9: U-Pb | E9: TIMS | F9: Monazite | G9: =IF('Working table'!$F70=$X$2,$Y$2,IF('Working table'!$F70=$X$3,$Y$3,IF('Working table'!$F70=$X$4,$Y$4,IF('Working table'!$F70=$X$5,$Y$5,$Y$6)))) -> Xtm | H9: 1819 | I9: 2 | J9: ±2 | K9: =H9 & " " & J9 -> 1819 ±2 | L9: =H9&" "&J9&" "&"("&G9&")" -> 1819 ±2 (Xtm) | M9: Metamorphic age | N9: Drill core | O9: 356.0-365.4 or 364.2-364.6 | P9: Moore - Tomblin | Q9: -105.05306 | R9: 57.47 | S9: 496791 | T9: 6369707 | U9: Annesley et al. 1999
A10: 99-4.2-(9.1) | B10: ZM-08 | C10: Foliated Granite | D10: U-Pb | E10: TIMS | F10: Zircon | G10: =IF('Working table'!$F87=$X$2,$Y$2,IF('Working table'!$F87=$X$3,$Y$3,IF('Working table'!$F87=$X$4,$Y$4,IF('Working table'!$F87=$X$5,$Y$5,$Y$6)))) -> Xtm | H10: 1818 | I10: 1 | J10: ±1 | K10: =H10 & " " & J10 -> 1818 ±1 | L10: =H10&" "&J10&" "&"("&G10&")" -> 1818 ±1 (Xtm) | M10: Crystallization age | N10: Drill core | O10: 437.8-438.1 or 440.8-441.1 | P10: Wheeler River | Q10: -105.30722 | R10: 57.508333 | S10: 481567 | T10: 6374041 | U10: Annesley et al. 1999
A11: 99-4.2-(9.1) | B11: ZM-08 | C11: Foliated Granite | D11: U-Pb | E11: TIMS | F11: Monazite | G11: =IF('Working table'!$F88=$X$2,$Y$2,IF('Working table'!$F88=$X$3,$Y$3,IF('Working table'!$F88=$X$4,$Y$4,IF('Working table'!$F88=$X$5,$Y$5,$Y$6)))) -> Xtm | H11: 1783 | I11: 2 | J11: ±2 | K11: =H11 & " " & J11 -> 1783 ±2 | L11: =H11&" "&J11&" "&"("&G11&")" -> 1783 ±2 (Xtm) | M11: Metamorphic age | N11: Drill core | O11: 437.8-438.1 or 440.8-441.1 | P11: Wheeler River | Q11: -105.30722 | R11: 57.508333 | S11: 481567 | T11: 6374041 | U11: Annesley et al. 1999
A12: 99-4.2-(9.1) | B12: ZM-08 | C12: Foliated Granite | D12: U-Pb | E12: TIMS | F12: Monazite | G12: =IF('Working table'!$F89=$X$2,$Y$2,IF('Working table'!$F89=$X$3,$Y$3,IF('Working table'!$F89=$X$4,$Y$4,IF('Working table'!$F89=$X$5,$Y$5,$Y$6)))) -> Xtm | H12: 1797 | I12: 1 | J12: ±1 | K12: =H12 & " " & J12 -> 1797 ±1 | L12: =H12&" "&J12&" "&"("&G12&")" -> 1797 ±1 (Xtm) | M12: Metamorphic age | N12: Drill core | O12: 437.8-438.1 or 440.8-441.1 | P12: Wheeler River | Q12: -105.30722 | R12: 57.508333 | S12: 481567 | T12: 6374041 | U12: Annesley et al. 1999
A13: 99-4.2-(9.1) | B13: ZM-08 | C13: Foliated Granite | D13: U-Pb | E13: TIMS | F13: Monazite | G13: =IF('Working table'!$F90=$X$2,$Y$2,IF('Working table'!$F90=$X$3,$Y$3,IF('Working table'!$F90=$X$4,$Y$4,IF('Working table'!$F90=$X$5,$Y$5,$Y$6)))) -> Xtm | H13: 1810 | I13: 1 | J13: ±1 | K13: =H13 & " " & J13 -> 1810 ±1 | L13: =H13&" "&J13&" "&"("&G13&")" -> 1810 ±1 (Xtm) | M13: Metamorphic age | N13: Drill core | O13: 437.8-438.1 or 440.8-441.0 | P13: Wheeler River | Q13: -105.30722 | R13: 57.508333 | S13: 481567 | T13: 6374041 | U13: Annesley et al. 1999
A14: 99-4.2-(9.2) | B14: A93-037a | C14: Foliated Grey Granite | D14: U-Pb | E14: TIMS | F14: Zircon | G14: =IF('Working table'!$F41=$X$2,$Y$2,IF('Working table'!$F41=$X$3,$Y$3,IF('Working table'!$F41=$X$4,$Y$4,IF('Working table'!$F41=$X$5,$Y$5,$Y$6)))) -> Xtm | H14: 1840 | I14: +11/-11 | J14: ±11 | K14: =H14 & " " & J14 -> 1840 ±11 | L14: =H14&" "&J14&" "&"("&G14&")" -> 1840 ±11 (Xtm) | M14: Crystallization age | N14: Outcrop | P14: Greenway Island | Q14: -103.33 | R14: 59.412778 | S14: 597570 | T14: 6475893 | U14: Annesley et al. 1997
A15: 99-4.2-(9.2) | B15: A93-037a | C15: Foliated Grey Granite | D15: U-Pb | E15: TIMS | F15: Monazite | G15: =IF('Working table'!$F42=$X$2,$Y$2,IF('Working table'!$F42=$X$3,$Y$3,IF('Working table'!$F42=$X$4,$Y$4,IF('Working table'!$F42=$X$5,$Y$5,$Y$6)))) -> Xtm | H15: 1790 | I15: 1 | J15: ±1 | K15: =H15 & " " & J15 -> 1790 ±1 | L15: =H15&" "&J15&" "&"("&G15&")" -> 1790 ±1 (Xtm) | M15: Metamorphic age | N15: Outcrop | P15: Greenway Island | Q15: -103.33 | R15: 59.412778 | S15: 597570 | T15: 6475893 | U15: Annesley et al. 1997 | V15: Annesley et al. 1994
A16: 99-4.2-(9.2) | B16: ST-1 | C16: Foliated leucotonalite (Trondhjemite) | D16: U-Pb | E16: TIMS | F16: Titanite | G16: =IF('Working table'!$F81=$X$2,$Y$2,IF('Working table'!$F81=$X$3,$Y$3,IF('Working table'!$F81=$X$4,$Y$4,IF('Working table'!$F81=$X$5,$Y$5,$Y$6)))) -> Xtm | H16: 1752 | I16: 2 | J16: ±2 | K16: =H16 & " " & J16 -> 1752 ±2 | L16: =H16&" "&J16&" "&"("&G16&")" -> 1752 ±2 (Xtm) | M16: Metamorphic age | N16: Drill core | P16: McClean Lake-Collins Creek | Q16: -103.90194 | R16: 58.225278 | S16: 564493 | T16: 6454320 | U16: Annesley et al. 1997 | V16: Annesley et al. 1996
B17: NN-2 | C17: Foliated meta-tonalite | D17: U-Pb | E17: ID-TIMS | F17: Zircon | G17: =IF('Working table'!$F92=$X$2,$Y$2,IF('Working table'!$F92=$X$3,$Y$3,IF('Working table'!$F92=$X$4,$Y$4,IF('Working table'!$F92=$X$5,$Y$5,$Y$6)))) -> Xtm | H17: 2612 | I17: 22 | J17: ±22 | K17: =H17 & " " & J17 -> 2612 ±22 | L17: =H17&" "&J17&" "&"("&G17&")" -> 2612 ±22 (Xtm) | M17: Crystallization age | N17: Drill core | P17: Russel Lake | U17: Annesley et al. 2007
B18: NN-2 | C18: Foliated meta-tonalite | D18: U-Pb | E18: ID-TIMS | F18: Monazite | G18: =IF('Working table'!$F93=$X$2,$Y$2,IF('Working table'!$F93=$X$3,$Y$3,IF('Working table'!$F93=$X$4,$Y$4,IF('Working table'!$F93=$X$5,$Y$5,$Y$6)))) -> Xtm | H18: 1803 | I18: 1 | J18: ±1 | K18: =H18 & " " & J18 -> 1803 ±1 | L18: =H18&" "&J18&" "&"("&G18&")" -> 1803 ±1 (Xtm) | M18: Metamorphic age | N18: Drill core | P18: Russel Lake | U18: Annesley et al. 2007
A19: 99-4.2-(9.2) | B19: A94-051 | C19: Granitic Gneiss | D19: U-Pb | E19: TIMS | F19: Zircon | G19: =IF('Working table'!$F46=$X$2,$Y$2,IF('Working table'!$F46=$X$3,$Y$3,IF('Working table'!$F46=$X$4,$Y$4,IF('Working table'!$F46=$X$5,$Y$5,$Y$6)))) -> Xtm | H19: 2626 | I19: +15/-13 | J19: ±15 | K19: =H19 & " " & J19 -> 2626 ±15 | L19: =H19&" "&J19&" "&"("&G19&")" -> 2626 ±15 (Xtm) | M19: Crystallization age | N19: Outcrop | P19: East of Black Island | Q19: -103.60528 | R19: 58.151111 | S19: 582082 | T19: 6446396 | U19: Annesley et al. 1997
A20: 99-4.2-(9.2) | B20: A94-051 | C20: Granitic Gneiss | D20: U-Pb | E20: TIMS | F20: Zircon | G20: =IF('Working table'!$F47=$X$2,$Y$2,IF('Working table'!$F47=$X$3,$Y$3,IF('Working table'!$F47=$X$4,$Y$4,IF('Working table'!$F47=$X$5,$Y$5,$Y$6)))) -> Ttn | H20: 1837 | I20: 34 | J20: ±34 | K20: =H20 & " " & J20 -> 1837 ±34 | L20: =H20&" "&J20&" "&"("&G20&")" -> 1837 ±34 (Ttn) | M20: Hudsonian metamorphism | N20: Outcrop | P20: East of Black Island | Q20: -103.60528 | R20: 58.151111 | S20: 582082 | T20: 6446396 | U20: Annesley et al. 1997
A21: 99-4.2-(9.1) | B21: MAC-65 | C21: Granitic Gneiss | D21: U-Pb | E21: TIMS | F21: Zircon | G21: =IF('Working table'!$F68=$X$2,$Y$2,IF('Working table'!$F68=$X$3,$Y$3,IF('Working table'!$F68=$X$4,$Y$4,IF('Working table'!$F68=$X$5,$Y$5,$Y$6)))) -> Xtm | H21: 2592 | I21: +7/-5 | J21: ±7 | K21: =H21 & " " & J21 -> 2592 ±7 | L21: =H21&" "&J21&" "&"("&G21&")" -> 2592 ±7 (Xtm) | M21: Crystallization age | N21: Drill core | O21: 268.5-269.0 or 272.9-273.3 or 286.3-286.7 | P21: McArthur River | Q21: -104.9825 | R21: 57.483889 | S21: 501020 | T21: 6371271 | U21: Annesley et al. 1999 | V21: Annesley et al. 1998
B22: NN-4 | C22: Granitic gneiss | D22: U-Pb | E22: ID-TIMS | F22: Zircon | G22: =IF('Working table'!$F94=$X$2,$Y$2,IF('Working table'!$F94=$X$3,$Y$3,IF('Working table'!$F94=$X$4,$Y$4,IF('Working table'!$F94=$X$5,$Y$5,$Y$6)))) -> Xtm | H22: 2583 | I22: 14 | J22: ±14 | K22: =H22 & " " & J22 -> 2583 ±14 | L22: =H22&" "&J22&" "&"("&G22&")" -> 2583 ±14 (Xtm) | M22: Crystallization age | N22: Drill core | P22: Russel Lake | U22: Annesley et al. 2007
B23: NN-4 | C23: Granitic gneiss | D23: U-Pb | E23: ID-TIMS | F23: Monazite | G23: =IF('Working table'!$F95=$X$2,$Y$2,IF('Working table'!$F95=$X$3,$Y$3,IF('Working table'!$F95=$X$4,$Y$4,IF('Working table'!$F95=$X$5,$Y$5,$Y$6)))) -> Xtm | H23: 1821.9 | I23: 2 | J23: ±2 | K23: =H23 & " " & J23 -> 1821.9 ±2 | L23: =H23&" "&J23&" "&"("&G23&")" -> 1821.9 ±2 (Xtm) | M23: Metamorphic age | N23: Drill core | P23: Russel Lake | U23: Annesley et al. 2007
B24: CX-30 | C24: Granitic pegmatite | D24: U-Pb | E24: ID-TIMS | F24: Zircon | G24: =IF('Working table'!$F60=$X$2,$Y$2,IF('Working table'!$F60=$X$3,$Y$3,IF('Working table'!$F60=$X$4,$Y$4,IF('Working table'!$F60=$X$5,$Y$5,$Y$6)))) -> Ttn | H24: 1816 | I24: 7 | J24: ±7 | K24: =H24 & " " & J24 -> 1816 ±7 | L24: =H24&" "&J24&" "&"("&G24&")" -> 1816 ±7 (Ttn) | M24: Crystallization age | N24: Drill core | O24: 713.0-713.6 | P24: Millenium Deposit | U24: Annesley et al. 2007
B25: CX-30 | C25: Granitic pegmatite | D25: U-Pb | E25: ID-TIMS | F25: Monazite | G25: =IF('Working table'!$F61=$X$2,$Y$2,IF('Working table'!$F61=$X$3,$Y$3,IF('Working table'!$F61=$X$4,$Y$4,IF('Working table'!$F61=$X$5,$Y$5,$Y$6)))) -> Ttn | H25: 1792.4 | I25: 1.2 | J25: ±1.2 | K25: =H25 & " " & J25 -> 1792.4 ±1.2 | L25: =H25&" "&J25&" "&"("&G25&")" -> 1792.4 ±1.2 (Ttn) | M25: Metamorphic age | N25: Drill core | O25: 713.0-713.6 | P25: Millenium Deposit | U25: Annesley et al. 2007
B26: MAC-257 | C26: Granitic pegmatite | D26: U-Pb | E26: ID-TIMS | F26: Monazite | G26: =IF('Working table'!$F64=$X$2,$Y$2,IF('Working table'!$F64=$X$3,$Y$3,IF('Working table'!$F64=$X$4,$Y$4,IF('Working table'!$F64=$X$5,$Y$5,$Y$6)))) -> Xtm | H26: 1814.6 | I26: 1.4 | J26: ±1.4 | K26: =H26 & " " & J26 -> 1814.6 ±1.4 | L26: =H26&" "&J26&" "&"("&G26&")" -> 1814.6 ±1.4 (Xtm) | M26: Crystallization age | N26: Drill core | O26: 636.5-636.9 | P26: McArthur River | U26: Annesley et al. 2007
B27: MAC-257 | C27: Granitic pegmatite | D27: U-Pb | E27: ID-TIMS | F27: Zircon | G27: =IF('Working table'!$F65=$X$2,$Y$2,IF('Working table'!$F65=$X$3,$Y$3,IF('Working table'!$F65=$X$4,$Y$4,IF('Working table'!$F65=$X$5,$Y$5,$Y$6)))) -> Xtm | H27: 1811.5 | I27: 5 | J27: ±5 | K27: =H27 & " " & J27 -> 1811.5 ±5 | L27: =H27&" "&J27&" "&"("&G27&")" -> 1811.5 ±5 (Xtm) | M27: Crystallization age | N27: Drill core | O27: 636.5-636.9 | P27: McArthur River | U27: Annesley et al. 2007
B28: WYL-09-46 | C28: Granitic pegmatite | D28: U-Pb | E28: Chemical age | F28: Monazite | G28: =IF('Working table'!$F82=$X$2,$Y$2,IF('Working table'!$F82=$X$3,$Y$3,IF('Working table'!$F82=$X$4,$Y$4,IF('Working table'!$F82=$X$5,$Y$5,$Y$6)))) -> Xtm | H28: 2.05-2.25 Ga | K28: =H28 & " " & J28 -> 2.05-2.25 Ga | L28: =H28&" "&J28&" "&"("&G28&")" -> 2.05-2.25 Ga (Xtm) | M28: Inherited age | N28: Drill core | O28: 32.6 | P28: Fraser Lake Zone B -Group B | U28: McKechnie et al., 2013
B29: WYL-10-62 | C29: Granitic pegmatite | D29: U-Pb | E29: Chemical age | F29: Uraninite | G29: =IF('Working table'!$F83=$X$2,$Y$2,IF('Working table'!$F83=$X$3,$Y$3,IF('Working table'!$F83=$X$4,$Y$4,IF('Working table'!$F83=$X$5,$Y$5,$Y$6)))) -> Ttn | H29: 1.8-1.85 Ga | K29: =H29 & " " & J29 -> 1.8-1.85 Ga | L29: =H29&" "&J29&" "&"("&G29&")" -> 1.8-1.85 Ga (Ttn) | M29: Crystallization age | N29: Drill core | O29: 93.5 | P29: Fraser Lake Zone B -Group A | U29: McKechnie et al., 2012
A30: 99-4.2-(9.2) | B30: A89-116 | C30: Granodioritic Gneiss | D30: U-Pb | E30: TIMS | F30: Zircon | G30: =IF('Working table'!$F14=$X$2,$Y$2,IF('Working table'!$F14=$X$3,$Y$3,IF('Working table'!$F14=$X$4,$Y$4,IF('Working table'!$F14=$X$5,$Y$5,$Y$6)))) -> Xtm | H30: 2620 | I30: +10/-9 | J30: ±10 | K30: =H30 & " " & J30 -> 2620 ±10 | L30: =H30&" "&J30&" "&"("&G30&")" -> 2620 ±10 (Xtm) | M30: Crystallization age | N30: Outcrop | P30: SE Rabbit Lake | Q30: -103.75694 | R30: 58.146667 | S30: 573125 | T30: 6445480 | U30: Annesley et al. 1992
A31: 99-4.2-(9.2) | B31: A89-116 | C31: Granodioritic Gneiss | D31: U-Pb | E31: TIMS | F31: Zircon | G31: =IF('Working table'!$F15=$X$2,$Y$2,IF('Working table'!$F15=$X$3,$Y$3,IF('Working table'!$F15=$X$4,$Y$4,IF('Working table'!$F15=$X$5,$Y$5,$Y$6)))) -> Xtm | H31: 1798 | I31: 14 | J31: ±14 | K31: =H31 & " " & J31 -> 1798 ±14 | L31: =H31&" "&J31&" "&"("&G31&")" -> 1798 ±14 (Xtm) | M31: Metamorphic age | N31: Outcrop | P31: SE Rabbit Lake | Q31: -103.75694 | R31: 58.146667 | S31: 573125 | T31: 6445480 | U31: Annesley et al. 1992
A32: 99-4.2-(9.2) | B32: A89-116 | C32: Granodioritic Gneiss | D32: U-Pb | E32: TIMS | F32: Titanite | G32: =IF('Working table'!$F16=$X$2,$Y$2,IF('Working table'!$F16=$X$3,$Y$3,IF('Working table'!$F16=$X$4,$Y$4,IF('Working table'!$F16=$X$5,$Y$5,$Y$6)))) -> Ttn | H32: 1789 | I32: 2 | J32: ±2 | K32: =H32 & " " & J32 -> 1789 ±2 | L32: =H32&" "&J32&" "&"("&G32&")" -> 1789 ±2 (Ttn) | M32: Metamorphic age | N32: Outcrop | P32: SE Rabbit Lake | Q32: -103.75694 | R32: 58.146667 | S32: 573125 | T32: 6445480 | U32: Annesley et al. 1992 | V32: Annesley et al. 1991
A33: 99-4.2-(9.1) | B33: A92-002b | C33: Granodioritic Gneiss | D33: U-Pb | E33: TIMS | F33: Titanite | G33: =IF('Working table'!$F28=$X$2,$Y$2,IF('Working table'!$F28=$X$3,$Y$3,IF('Working table'!$F28=$X$4,$Y$4,IF('Working table'!$F28=$X$5,$Y$5,$Y$6)))) -> Xtm | H33: 1792 | I33: 4 | J33: ±4 | K33: =H33 & " " & J33 -> 1792 ±4 | L33: =H33&" "&J33&" "&"("&G33&")" -> 1792 ±4 (Xtm) | M33: Metamorphic age | N33: Outcrop | P33: Karpinka Lake | Q33: -106.13 | R33: 56.955833 | S33: 431247 | T33: 6313050 | U33: Annesley et al. 1997
A34: 99-4.2-(9.2) | B34: A90-011b | C34: Grey Granite (sheared) | D34: U-Pb | E34: TIMS | F34: Zircon | G34: =IF('Working table'!$F22=$X$2,$Y$2,IF('Working table'!$F22=$X$3,$Y$3,IF('Working table'!$F22=$X$4,$Y$4,IF('Working table'!$F22=$X$5,$Y$5,$Y$6)))) -> Xtm | H34: 1719 | I34: 1 | J34: ±1 | K34: =H34 & " " & J34 -> 1719 ±1 | L34: =H34&" "&J34&" "&"("&G34&")" -> 1719 ±1 (Xtm) | M34: Metamorphic age | N34: Outcrop | P34: Hidden Bay | Q34: -103.58528 | R34: 58.208333 | S34: 583112 | T34: 6452798 | U34: Unpublished
A35: 99-4.2-(9.2) | B35: A90-011b | C35: Grey Granite (sheared) | D35: U-Pb | E35: TIMS | F35: Monazite | G35: =IF('Working table'!$F23=$X$2,$Y$2,IF('Working table'!$F23=$X$3,$Y$3,IF('Working table'!$F23=$X$4,$Y$4,IF('Working table'!$F23=$X$5,$Y$5,$Y$6)))) -> Xtm | H35: 1782 | I35: 1 | J35: ±1 | K35: =H35 & " " & J35 -> 1782 ±1 | L35: =H35&" "&J35&" "&"("&G35&")" -> 1782 ±1 (Xtm) | M35: Metamorphic age | N35: Outcrop | P35: Hidden Bay | Q35: -103.58528 | R35: 58.208333 | S35: 583112 | T35: 6452798 | U35: Unpublished
A36: 99-4.2-(9.1) | B36: P-25 | C36: Grey Orthogneiss | D36: U-Pb | E36: TIMS | F36: Zircon | G36: =IF('Working table'!$F71=$X$2,$Y$2,IF('Working table'!$F71=$X$3,$Y$3,IF('Working table'!$F71=$X$4,$Y$4,IF('Working table'!$F71=$X$5,$Y$5,$Y$6)))) -> Xtm | H36: 2786 | I36: 7 | J36: ±7 | K36: =H36 & " " & J36 -> 2786 ±7 | L36: =H36&" "&J36&" "&"("&G36&")" -> 2786 ±7 (Xtm) | M36: Crystallization age | N36: Drill core | O36: 97.0-97.3 or 101.7-102.5 | P36: P-Patch | Q36: -105.57694 | R36: 57.220278 | S36: 465124 | T36: 6342069 | U36: Annesley et al. 1999 | V36: Annesley et al. 1999b
A37: 99-4.2-(9.1) | B37: P-25 | C37: Grey Orthogneiss | D37: U-Pb | E37: TIMS | F37: Zircon | G37: =IF('Working table'!$F72=$X$2,$Y$2,IF('Working table'!$F72=$X$3,$Y$3,IF('Working table'!$F72=$X$4,$Y$4,IF('Working table'!$F72=$X$5,$Y$5,$Y$6)))) -> Xtm | H37: 1813 | I37: 6 | J37: ±6 | K37: =H37 & " " & J37 -> 1813 ±6 | L37: =H37&" "&J37&" "&"("&G37&")" -> 1813 ±6 (Xtm) | M37: Metamorphic age | N37: Drill core | O37: 97.0-97.3 or 101.7-102.3 | P37: P-Patch | Q37: -105.57694 | R37: 57.220278 | S37: 465124 | T37: 6342069 | U37: Annesley et al. 1999 | V37: Annesley et al. 1999b
A38: 99-4.2-(9.1) | B38: P-25 | C38: Grey Orthogneiss | D38: U-Pb | E38: TIMS | F38: Monazite | G38: =IF('Working table'!$F73=$X$2,$Y$2,IF('Working table'!$F73=$X$3,$Y$3,IF('Working table'!$F73=$X$4,$Y$4,IF('Working table'!$F73=$X$5,$Y$5,$Y$6)))) -> Xtm | H38: 1814 | I38: 1 | J38: ±1 | K38: =H38 & " " & J38 -> 1814 ±1 | L38: =H38&" "&J38&" "&"("&G38&")" -> 1814 ±1 (Xtm) | M38: Metamorphic age | N38: Drill core | O38: 97.0-97.3 or 101.7-102.4 | P38: P-Patch | Q38: -105.57694 | R38: 57.220278 | S38: 465124 | T38: 6342069 | U38: Annesley et al. 1999 | V38: Annesley et al. 1999b
A39: 99-4.2-(9.1) | B39: CB94-043 | C39: Grey Tonalitic Gneiss | D39: U-Pb | E39: TIMS | F39: Zircon | G39: =IF('Working table'!$F48=$X$2,$Y$2,IF('Working table'!$F48=$X$3,$Y$3,IF('Working table'!$F48=$X$4,$Y$4,IF('Working table'!$F48=$X$5,$Y$5,$Y$6)))) -> Xtm | H39: 1818 | I39: 1 | J39: ±1 | K39: =H39 & " " & J39 -> 1818 ±1 | L39: =H39&" "&J39&" "&"("&G39&")" -> 1818 ±1 (Xtm) | M39: Crystallization age | N39: Drill core | O39: 521.0-521.8 | P39: Yalowega Lake | Q39: -104.85833 | R39: 57.854444 | S39: 508376 | T39: 6412529 | U39: Annesley et al. 1999 | V39: Annesley et al. 1998
A40: 99-4.2-(9.1) | B40: CB94-043 | C40: Grey Tonalitic Gneiss | D40: U-Pb | E40: TIMS | F40: Monazite | G40: =IF('Working table'!$F49=$X$2,$Y$2,IF('Working table'!$F49=$X$3,$Y$3,IF('Working table'!$F49=$X$4,$Y$4,IF('Working table'!$F49=$X$5,$Y$5,$Y$6)))) -> Xtm | H40: 1801 | I40: 1 | J40: ±1 | K40: =H40 & " " & J40 -> 1801 ±1 | L40: =H40&" "&J40&" "&"("&G40&")" -> 1801 ±1 (Xtm) | M40: Metamorphic age | N40: Drill core | O40: 521.0-521.7 | P40: Yalowega Lake | Q40: -104.85833 | R40: 57.854444 | S40: 508376 | T40: 6412529 | U40: Annesley et al. 1999 | V40: Annesley et al. 1998
...

Sheet Raw
A1: Map | B1: Sample | C1: Rock | D1: System | E1: Technique | F1: Mineral | G1: Age | H1: Analytical/Internal uncertainty (X) | I1: Interpretation | J1: Sample type | K1: Depth | L1: Area | M1: longitute | N1: Latitute2 | O1: UTM E | P1: UTM N | Q1: Column4 | R1: Column5
A2: 99-4.2-(9.2) | B2: A90-006 | C2: Quartz Dioritic Gneiss | D2: U-Pb | E2: TIMS | F2: Zircon | G2: 2638 | H2: +65/-60 | I2: Crystallization age | J2: Outcrop | L2: Ashley Peninsula | M2: 58.133889 | N2: 58.133889 | O2: 587482 | P2: 6444603 | Q2: Annesley et al. 1992
A3: 99-4.2-(9.2) | B3: A90-006 | C3: Quartz Dioritic Gneiss | D3: U-Pb | E3: TIMS | F3: Titanite | G3: 1779 | H3: 2 | I3: Metamorphic age | J3: Outcrop | L3: Ashley Peninsula | M3: 58.133889 | N3: 58.133889 | O3: 587482 | P3: 6444603 | Q3: Annesley et al. 1992 | R3: Annesley et al. 1991
A4: 99-4.2-(9.2) | B4: A90-005b | C4: Tonalitic Gneiss | D4: U-Pb | E4: TIMS | F4: Zircon | G4: 2689 | H4: +19/-18 | I4: Crystallization age | J4: Outcrop | L4: Ashley Peninsula | M4: 58.077778 | N4: 58.077778 | O4: 586788 | P4: 6438323 | Q4: Annesley et al. 1992 | R4: Annesley et al. 1991
A5: 99-4.2-(9.2) | B5: A90-005b | C5: Tonalitic Gneiss | D5: U-Pb | E5: TIMS | F5: Titanite | G5: 1778 | H5: 2 | I5: Metamorphic age | J5: Outcrop | L5: Ashley Peninsula | M5: 58.077778 | N5: 58.077778 | O5: 586788 | P5: 6438323 | Q5: Annesley et al. 1992 | R5: Annesley et al. 1991
A6: 99-4.2-(9.2) | B6: A90-005b | C6: Tonalitic Gneiss | D6: U-Pb | E6: TIMS | F6: Zircon | G6: 2566 | H6: +23/-21 | I6: Metamorphic age | J6: Outcrop | L6: Ashley Peninsula | M6: 58.077778 | N6: 58.077778 | O6: 586788 | P6: 6438323 | Q6: Annesley et al. 1992 | R6: Annesley et al. 1991
B7: CLC1-123 | C7: Tonalitic Gneiss | D7: U-Pb | E7: ID-TIMS | F7: Zircon | G7: 2714 | H7: 12 | I7: Crystallization age | J7: Drill core | K7: 653.4-653.9 | L7: Close Lake | Q7: Annesley et al. 2003
B8: CLC1-123 | C8: Tonalitic Gneiss | D8: U-Pb | E8: ID-TIMS | F8: Monazite | G8: 1805.5 | H8: 1.4 | I8: Thermal metamorphic | J8: Drill core | K8: 653.4-653.9 | L8: Close Lake | Q8: Annesley et al. 2003
A9: 99-4.2-(9.2) | B9: 230 | C9: Pegmatite | D9: U-Pb | E9: TIMS | F9: Zircon | G9: 1923 | H9: +8/-7 | I9: Crystallization age (upper intercept) | J9: Drill core | L9: Dawn Lake | M9: 58.303611 | N9: 58.303611 | O9: 560734 | P9: 6462976 | Q9: Annesley et al. 1997
A10: 99-4.2-(9.2) | B10: 230 | C10: Pegmatite | D10: U-Pb | E10: TIMS | F10: Zircon | G10: 1127 | H10: 5 | I10: lower intercept | J10: Drill core | L10: Dawn Lake | M10: 58.303611 | N10: 58.303611 | O10: 560734 | P10: 6462976 | Q10: Annesley et al. 1997
A11: 99-4.2-(9.2) | B11: 230 | C11: Pegmatite | D11: U-Pb | E11: TIMS | F11: Monazite | G11: 1766 | H11: 1 | I11: Metamorphic age | J11: Drill core | L11: Dawn Lake | M11: 58.303611 | N11: 58.303611 | O11: 560734 | P11: 6462976 | Q11: Annesley et al. 1997
A12: 99-4.2-(9.2) | B12: 230 | C12: Pegmatite | D12: U-Pb | E12: TIMS | F12: Xenotime | G12: 1767 | H12: 2 | I12: Metamorphic age | J12: Drill core | L12: Dawn Lake | M12: 58.303611 | N12: 58.303611 | O12: 560734 | P12: 6462976 | Q12: Annesley et al. 1997
A13: 99-4.2-(9.2) | B13: EPE-20A | C13: Foliated Grey Granite | D13: U-Pb | E13: TIMS | F13: Zircon | G13: 1850-1835 | I13: Intrusive age | J13: Drill core | L13: Eagle Point | M13: -103.59528 | N13: 58.295556 | O13: 582340 | P13: 6462485 | Q13: Annesley et al. 1997
A14: 99-4.2-(9.2) | B14: EPE-20A | C14: Foliated Grey Granite | D14: U-Pb | E14: TIMS | F14: Monazite | G14: 1803 | H14: 4 | I14: Metamorphic age | J14: Drill core | L14: Eagle Point | M14: -103.59528 | N14: 58.295556 | O14: 582340 | P14: 6462485 | Q14: Annesley et al. 1997
A15: 99-4.2-(9.2) | B15: EPE-21 | C15: Foliated Grey Granite | D15: U-Pb | E15: TIMS | F15: Monazite | G15: 1813 | H15: 2 | I15: Metamorphic age | J15: Drill core | L15: Eagle Point | M15: -103.59667 | N15: 58.294444 | O15: 582263 | P15: 6462356 | Q15: Annesley et al. 1997
A16: 99-4.2-(9.2) | B16: A94-051 | C16: Granitic Gneiss | D16: U-Pb | E16: TIMS | F16: Zircon | G16: 2626 | H16: +15/-13 | I16: Crystallization age (upper intercept) | J16: Outcrop | L16: East of Black Island | M16: -103.60528 | N16: 58.151111 | O16: 582082 | P16: 6446396 | Q16: Annesley et al. 1997
A17: 99-4.2-(9.2) | B17: A94-051 | C17: Granitic Gneiss | D17: U-Pb | E17: TIMS | F17: Zircon | G17: 1837 | H17: 34 | I17: Hudsonian metamorphism (lower intercept) | J17: Outcrop | L17: East of Black Island | M17: -103.60528 | N17: 58.151111 | O17: 582082 | P17: 6446396 | Q17: Annesley et al. 1997
A18: 99-4.2-(9.2) | B18: A94-025a | C18: Metasomatized Pegmatite | D18: U-Pb | E18: TIMS | F18: Zircon | G18: 1808 | H18: 4 | I18: Metamorphic age | J18: Outcrop | L18: East of Black Island | M18: -103.58528 | N18: 58.147778 | O18: 583268 | P18: 6446044 | Q18: Annesley et al. 1997 | R18: Annesley and Madore, 1997
A19: 99-4.2-(9.1) | B19: EL-09 | C19: Pegmatite | D19: U-Pb | E19: TIMS | F19: Zircon | G19: 1819 | H19: 6 | I19: Crystallization age | J19: Drill core | K19: 839.8-840.4 | L19: Epp Lake | M19: 57.870833 | N19: 57.870833 | O19: 489315 | P19: 6414369 | R19: Madore et al. 1999
A20: 99-4.2-(9.1) | B20: EL-09 | C20: Pegmatite | D20: U-Pb | E20: TIMS | F20: Zircon | G20: 1224 | H20: 6 | I20: Lower intercept recrystallization age | J20: Drill core | K20: 839.8-840.3 | L20: Epp Lake | M20: 57.870833 | N20: 57.870833 | O20: 489315 | P20: 6414369 | Q20: Annesley et al. 1999 | R20: Madore et al. 1999
A21: 99-4.2-(9.2) | B21: A93-036 | C21: Foliated Granite | D21: U-Pb | E21: TIMS | F21: Zircon | G21: 2726 | H21: 5 | I21: Crystallization age | J21: Outcrop | L21: Fife Island | M21: -103.3525 | N21: 58.42 | O21: 596240 | P21: 6476663 | Q21: Annesley et al. 1997
B22: WYL-09-50 | C22: Pegmatite | D22: U-Pb | E22: SIMS | F22: Uraninite | G22: 1730 | H22: 30 | I22: Upper intercept | K22: 233 | L22: Fraser Lake Zone B | Q22: Mercadier et al., 2013
B23: WYL-10-62 | C23: Granitic pegmatite | D23: U-Pb | E23: Chemical age | F23: Uraninite | G23: 1.8-1.85 Ga | I23: Crystallization | J23: Drill core | K23: 93.5 | L23: Fraser Lake Zone B -Group A | Q23: McKechnie et al., 2012
B24: WYL-09-46 | C24: Granitic pegmatite | D24: U-Pb | E24: Chemical age | F24: Monazite | G24: 2.05-2.25 Ga | I24: Inherited age | J24: Drill core | K24: 32.6 | L24: Fraser Lake Zone B -Group B | Q24: McKechnie et al., 2013
A25: 99-4.2-(9.2) | B25: A93-037a | C25: Foliated Grey Granite | D25: U-Pb | E25: TIMS | F25: Zircon | G25: 1840 | H25: +11/-9 | I25: Crystallization age | J25: Outcrop | L25: Greenway Island | M25: -103.33 | N25: 59.412778 | O25: 597570 | P25: 6475893 | Q25: Annesley et al. 1997
A26: 99-4.2-(9.2) | B26: A93-037a | C26: Foliated Grey Granite | D26: U-Pb | E26: TIMS | F26: Monazite | G26: 1790 | H26: 1 | I26: Metamorphic age | J26: Outcrop | L26: Greenway Island | M26: -103.33 | N26: 59.412778 | O26: 597570 | P26: 6475893 | Q26: Annesley et al. 1997 | R26: Annesley et al. 1994
A27: 99-4.2-(9.2) | B27: A93-037b | C27: Pegmatite | D27: U-Pb | E27: TIMS | F27: Zircon | G27: 1819 | H27: 6 | I27: Crystallization age | J27: Outcrop | L27: Greenway Island | M27: 58.412778 | N27: 58.412778 | O27: 597570 | P27: 6475893 | Q27: Annesley et al. 1997 | R27: Annesley and Madore, 1997
A28: 99-4.2-(9.2) | B28: A94-040a | C28: Porphyritic Granite | D28: U-Pb | E28: TIMS | F28: Zircon | G28: 1812 | H28: 3 | I28: Crystallization age | J28: Outcrop | L28: Harrison Peninsula | M28: 58.304167 | N28: 58.304167 | O28: 585691 | P28: 6463495 | Q28: Annesley et al. 1997 | R28: Annesley et al. 1995
A29: 99-4.2-(9.2) | B29: A90-011b | C29: Grey Granite (sheared) | D29: U-Pb | E29: TIMS | F29: Zircon | G29: 1719 | H29: 1 | I29: Metamorphic age | J29: Outcrop | L29: Hidden Bay | M29: -103.58528 | N29: 58.208333 | O29: 583112 | P29: 6452798 | Q29: Unpublished
A30: 99-4.2-(9.2) | B30: A90-011b | C30: Grey Granite (sheared) | D30: U-Pb | E30: TIMS | F30: Monazite | G30: 1782 | H30: 1 | I30: Metamorphic age | J30: Outcrop | L30: Hidden Bay | M30: -103.58528 | N30: 58.208333 | O30: 583112 | P30: 6452798 | Q30: Unpublished
A31: 99-4.2-(9.2) | B31: A90-012a | C31: Meta-gabbro | D31: U-Pb | E31: TIMS | F31: Zircon | G31: 1820 | H31: 5 | I31: Crystallization age | J31: Outcrop | L31: Hidden Bay | M31: -103.59722 | N31: 58.205556 | O31: 583144 | P31: 6452482 | Q31: Annesley et al. 1992
A32: 99-4.2-(9.2) | B32: A89-114 | C32: Meta-quartzite | D32: U-Pb | E32: TIMS | F32: Zircon | G32: 2686-2863 | H32: NA | I32: Detrital age | J32: Outcrop | L32: Hidden Bay | M32: -103.76 | N32: 58.144167 | O32: 572965 | P32: 6445460 | Q32: Annesley et al. 1992
A33: 99-4.2-(9.2) | B33: A89-114 | C33: Meta-quartzite | D33: U-Pb | E33: TIMS | F33: Monazite | G33: 1816 | H33: 2 | I33: Metamorphic age | J33: Outcrop | L33: Hidden Bay | M33: -103.76 | N33: 58.144167 | O33: 572965 | P33: 6445460 | Q33: Annesley et al. 1992
A34: 99-4.2-(9.2) | B34: A89-108 | C34: Pelitic Gneiss | D34: U-Pb | E34: TIMS | F34: Monazite | G34: 1812 | H34: 2 | I34: Metamorphic age | J34: Outcrop | L34: Hidden Bay | M34: 58.149722 | N34: 58.149722 | O34: 573147 | P34: 6446066 | Q34: Annesley et al. 1992
A35: 99-4.2-(9.2) | B35: A89-100 | C35: Porphyritic Granite | D35: U-Pb | E35: TIMS | F35: Zircon | G35: 1815 | H35: 2 | I35: Crystallization age | J35: Outcrop | L35: Hidden Bay | M35: 58.176389 | N35: 58.176389 | O35: 574567 | P35: 6449063 | Q35: Annesley et al. 1992
A36: 99-4.2-(9.2) | B36: A89-100 | C36: Porphyritic Granite | D36: U-Pb | E36: TIMS | F36: Titanite | G36: 1788 | H36: 2 | I36: Metamorphic age | J36: Outcrop | L36: Hidden Bay | M36: 58.176389 | N36: 58.176389 | O36: 574567 | P36: 6449063 | Q36: Annesley et al. 1992
C37: U vein | D37: U-Pb | E37: SIMS | F37: Uraninite | G37: 1774 | H37: 9 | I37: Upper intercept (grey zone) | L37: Hook Lake | Q37: Mercadier et al., 2013
C38: U vein | D38: U-Pb | E38: SIMS | F38: Uraninite | G38: 1805 | H38: 1 | I38: Upper intercept (white zone) | L38: Hook Lake | Q38: Mercadier et al., 2013
D39: U-Pb | E39: Chemical age | F39: Uraninite | G39: 1.7-1.9 | L39: Hook Lake (white zone), Fraser Lake WYL09-50-233, Nob Hill | Q39: Mercadier et al., 2013
D40: U-Pb | E40: Chemical age | F40: Uraninite | G40: 1.6-1.7 | L40: Hooke Lake (grey zone), Fraser Lake Trench 2, Moore Lakes | Q40: Mercadier et al., 2013
...

Sheet Working table (2)
A1: Map | B1: Sample | C1: Rock | D1: System | E1: Technique | F1: Mineral | G1: Min_label | H1: Age | I1: Analytical/Internal uncertainty (X) | J1: Interpretation | K1: Sample type | L1: Depth | M1: Area | N1: longitute | O1: Latitute2 | P1: UTM E | Q1: UTM N | R1: Column4 | S1: Column5
